Workbook

Sheet Read me
A1: JioMausam: every number, recalculated from the data
A2: This workbook recomputes the numbers in our pitch with live formulas. Change a yellow cell and everything that depends on it updates.
A4: Colour code
A5: Blue text: an input you can change (yellow fill marks the key ones).
A6: Black text: a formula.
A7: Green text: a value pulled from another sheet.
A9: Sheets
A10: Calibration: the one scale factor (K = 1.17), fitted on the tuning days 10–12 May 2018 only.
A11: Network hourly: average rain over all 500 links, ours vs radar, for every hour. The correlation on the unseen test days is the 0.95.
A12: Link scores: each link scored on its own on the unseen days. The median is the 0.88; the share above 0.7 is the 91%.
A13: Payout test: 14,256 decisions (1,782 squares × 8 test days). Change the trigger and watch events caught and false triggers move.
A14: India daily: 27,103 days of IMD station reports for Mumbai (Santacruz), Nagpur and Ahmedabad, 2000–2024.
... A22: India: IMD synoptic station reports via NOAA Global Summary of the Day (noaa-gsod-pds.s3.amazonaws.com). Units converted (inches to mm, °F to °C); years with fewer than 330 reports or fewer than 110 monsoon-season reports dropped.

Sheet Calibration
A1: Calibration: one scale factor for the whole network, from the tuning days only
A2: Our raw estimate tends to read low. K scales it so that, over 10–12 May, our total rain equals radar’s total. The test days (13–20 May) are never used here.
A4: Radar total, tuning days (mm·h summed over all links) | B4: =SUM(C9:C508) -> 2758.0488
A5: Our uncalibrated total, tuning days | B5: =SUM(B9:B508) -> 2351.9168
A6: K = radar total ÷ our total | B6: =B4/B5 -> 1.1726813
A8: Link | B8: Ours, uncalibrated: sum of hourly rain on tuning days (mm) | C8: Radar along the link: same sum (mm)
A9: 0 | B9: 0.471185 | C9: 0.691557
A10: 1 | B10: 8.786381 | C10: 6.388367
A11: 2 | B11: 0.155342 | C11: 0.074394
A12: 3 | B12: 0.688193 | C12: 0.015062
A13: 4 | B13: 0.359344 | C13: 0.923398
A14: 5 | B14: 0.035874 | C14: 0.412417
A15: 6 | B15: 1.834969 | C15: 1.57157
A16: 7 | B16: 0.063165 | C16: 0.000162
A17: 8 | B17: 0.041132 | C17: 0.015452
A18: 9 | B18: 0.00396 | C18: 0.128326
A19: 10 | B19: 0.121507 | C19: 0.11684
A20: 11 | B20: 1.284347 | C20: 0.246924
... A508: 499 | B508: 7.290303 | C508: 3.655329

Sheet Network hourly
A1: Network average, hour by hour: our estimate vs radar
A2: Each row averages all 500 links for one hour. Rows 6–77 are tuning hours (10–12 May); rows 78–269 are the unseen test hours (13–20 May).
F4: Scale factor K | G4: =Calibration!B6 -> 1.1726813
A5: Hour (UTC) | B5: Period | C5: Ours, uncalibrated (mm/h) | D5: Ours, calibrated (mm/h) | E5: Radar (mm/h) | F5: Correlation, test hours (the 0.95) | G5: =CORREL(D78:D269,E78:E269) -> 0.95306542
A6: 2018-05-10 00:00 | B6: tuning | C6: 0.0091353907 | D6: =C6*$G$4 -> 0.010712902 | E6: 0.0081347604 | F6: Correlation, tuning hours | G6: =CORREL(D6:D77,E6:E77) -> 0.96796457
A7: 2018-05-10 01:00 | B7: tuning | C7: 0.043615106 | D7: =C7*$G$4 -> 0.051146618 | E7: 0.031193048 | F7: Our total ÷ radar total, test hours | G7: =SUM(D78:D269)/SUM(E78:E269) -> 0.81822087
A8: 2018-05-10 02:00 | B8: tuning | C8: 0.056294244 | D8: =C8*$G$4 -> 0.066015205 | E8: 0.070381315
A9: 2018-05-10 03:00 | B9: tuning | C9: 0.077224746 | D9: =C9*$G$4 -> 0.090560013 | E9: 0.069432758 | F9: Why correlation ignores K: multiplying every value by the same number changes the size, not the up-and-down pattern. K fixes the totals; the correlation was already there.
A10: 2018-05-10 04:00 | B10: tuning | C10: 0.087429863 | D10: =C10*$G$4 -> 0.10252736 | E10: 0.1321231
A11: 2018-05-10 05:00 | B11: tuning | C11: 0.067280723 | D11: =C11*$G$4 -> 0.078898843 | E11: 0.12714842
A12: 2018-05-10 06:00 | B12: tuning | C12: 0.039973622 | D12: =C12*$G$4 -> 0.046876317 | E12: 0.099236007
A13: 2018-05-10 07:00 | B13: tuning | C13: 0.017452454 | D13: =C13*$G$4 -> 0.020466166 | E13: 0.032096539
A14: 2018-05-10 08:00 | B14: tuning | C14: 0.039616407 | D14: =C14*$G$4 -> 0.046457418 | E14: 0.062030473
A15: 2018-05-10 09:00 | B15: tuning | C15: 0.077313401 | D15: =C15*$G$4 -> 0.090663976 | E15: 0.14175009
A16: 2018-05-10 10:00 | B16: tuning | C16: 0.31259729 | D16: =C16*$G$4 -> 0.36657698 | E16: 0.36175705
A17: 2018-05-10 11:00 | B17: tuning | C17: 0.53688734 | D17: =C17*$G$4 -> 0.62959773 | E17: 0.80290916
A18: 2018-05-10 12:00 | B18: tuning | C18: 0.63938526 | D18: =C18*$G$4 -> 0.74979511 | E18: 1.0440807
A19: 2018-05-10 13:00 | B19: tuning | C19: 0.47079869 | D19: =C19*$G$4 -> 0.5520968 | E19: 0.51297163
A20: 2018-05-10 14:00 | B20: tuning | C20: 0.45788975 | D20: =C20*$G$4 -> 0.53695873 | E20: 0.44358382
A21: 2018-05-10 15:00 | B21: tuning | C21: 0.28530726 | D21: =C21*$G$4 -> 0.33457448 | E21: 0.25374199
... A269: 2018-05-20 23:00 | B269: test | C269: 0.0054734736 | D269: =C269*$G$4 -> 0.0064186399 | E269: 0

Sheet Link scores
A1: Each link on its own, scored on the unseen days
A2: Correlation between our hourly rain and radar along the same path, 13–20 May, computed by rain_pipeline.py. Links with too little rain on those days are not scored.
J4: Links scored | K4: =COUNT(E9:E508) -> 490
J5: Median correlation (the 0.88) | K5: =MEDIAN(E9:E508) -> 0.881649
J6: Share of links above | K6: 0.7
J7: Share (the 91%) | K7: =COUNTIF(E9:E508,">"&K6)/K4 -> 0.90612245
A8: Link | B8: Length (km) | C8: Frequency (GHz) | D8: Polarization | E8: Correlation on unseen days | F8: Our rain, test days (mm) | G8: Radar, test days (mm) | H8: Wet threshold, channel 1 (dB)
A9: 0 | B9: 6.179169 | C9: 24.913 | D9: V | E9: 0.902604 | F9: 40.246105 | G9: 44.619272 | H9: 0.556489
A10: 1 | B10: 5.672759 | C10: 18.195 | D10: H | E10: 0.91072 | F10: 41.559624 | G10: 38.783563 | H10: 0.574994
A11: 2 | B11: 7.520492 | C11: 24.913 | D11: V | E11: 0.922612 | F11: 36.094895 | G11: 36.458751 | H11: 0.562716
A12: 3 | B12: 11.960403 | C12: 19.205 | D12: V | E12: 0.970058 | F12: 48.436622 | G12: 47.785735 | H12: 0.735407
A13: 4 | B13: 4.806653 | C13: 25.977 | D13: V | E13: 0.894697 | F13: 41.85112 | G13: 33.11697 | H13: 0.29206
A14: 5 | B14: 7.69067 | C14: 24.913 | D14: V | E14: 0.909425 | F14: 39.329174 | G14: 40.494004 | H14: 0.284445
A15: 6 | B15: 4.423809 | C15: 32.347 | D15: V | E15: 0.885369 | F15: 30.68974 | G15: 32.35042 | H15: 0.626764
A16: 7 | B16: 4.246997 | C16: 25.417 | D16: V | E16: 0.885611 | F16: 33.380515 | G16: 37.079122 | H16: 0.565606
A17: 8 | B17: 5.481442 | C17: 25.417 | D17: H | E17: 0.923124 | F17: 38.098726 | G17: 39.155364 | H17: 0.548292
A18: 9 | B18: 9.998667 | C18: 18.14 | D18: V | E18: 0.957988 | F18: 43.074872 | G18: 44.381376 | H18: 0.56907
A19: 10 | B19: 2.861634 | C19: 37.422 | D19: V | E19: 0.902075 | F19: 31.692913 | G19: 44.447829 | H19: 0.207729
A20: 11 | B20: 5.53374 | C20: 25.865 | D20: V | E20: 0.90939 | F20: 32.669397 | G20: 43.493674 | H20: 0.462602
... A61: 52 | B61: 2.321372 | C61: 32.347 | D61: V | E61: 0.936131 | F61: 56.20796 | G61: 51.486676 | H61: 0.349114
A62: 53 | B62: 3.104235 | C62: 32.347 | D62: V | F62: 54.853158 | G62: 0 | H62: 0.279944
A63: 54 | B63: 3.351849 | C63: 32.347 | D63: V | E63: 0.80917 | F63: 8.288488 | G63: 15.753105 | H63: 0.314709
A64: 55 | B64: 7.514676 | C64: 24.913 | D64: V | E64: 0.546128 | F64: 7.70575 | G64: 11.048492 | H64: 0.563903
A65: 56 | B65: 5.01014 | C65: 25.921 | D65: H | E65: 0.750407 | F65: 10.187878 | G65: 15.372073 | H65: 0.549637
A66: 57 | B66: 5.553627 | C66: 24.913 | D66: H | E66: 0.864263 | F66: 39.117411 | G66: 35.148496 | H66: 0.561898
A67: 58 | B67: 5.848867 | C67: 24.913 | D67: V | E67: 0.54983 | F67: 9.698107 | G67: 17.571365 | H67: 0.4032
A68: 59 | B68: 7.892416 | C68: 23.086 | D68: V | E68: 0.833904 | F68: 23.479072 | G68: 45.502432 | H68: 0.331295
A69: 60 | B69: 7.012147 | C69: 25.865 | D69: V | E69: 0.700028 | F69: 4.881033 | G69: 12.766817 | H69: 0.2352
A70: 61 | B70: 4.85663 | C70: 24.913 | D70: V | E70: 0.220293 | F70: 26.99634 | G70: 54.357834 | H70: 0.456954
A71: 62 | B71: 6.586658 | C71: 24.913 | D71: V | E71: 0.673975 | F71: 20.537804 | G71: 24.906341 | H71: 0.311907
A72: 63 | B72: 2.432185 | C72: 37.422 | D72: V | E72: 0.964406 | F72: 44.115231 | G72: 43.038453 | H72: 0.467558
A73: 64 | B73: 3.877997 | C73: 25.921 | D73: V | E73: 0.777449 | F73: 21.362378 | G73: 36.06703 | H73: 0.581558
A74: 65 | B74: 2.940076 | C74: 37.422 | D74: V | E74: 0.700605 | F74: 10.422075 | G74: 16.806891 | H74: 0.548673
... A99: 90 | B99: 8.289014 | C99: 23.086 | D99: V | E99: 0.971512 | F99: 32.844576 | G99: 50.120244 | H99: 0.342059
A100: 91 | B100: 1.049176 | C100: 37.422 | D100: H | F100: 80.365009 | G100: 0 | H100: 0.565175
A101: 92 | B101: 11.567748 | C101: 18.14 | D101: V | E101: 0.873902 | F101: 54.675426 | G101: 51.567003 | H101: 0.608118
A102: 93 | B102: 7.610981 | C102: 24.913 | D102: V | E102: 0.902413 | F102: 32.461533 | G102: 41.173056 | H102: 0.575454
A103: 94 | B103: 5.428651 | C103: 26.425 | D103: V | E103: 0.72461 | F103: 13.467848 | G103: 14.671578 | H103: 0.467826
A104: 95 | B104: 6.273806 | C104: 25.417 | D104: H | E104: 0.916175 | F104: 44.523982 | G104: 39.252278 | H104: 0.485975
A105: 96 | B105: 5.563154 | C105: 24.913 | D105: H | E105: 0.2985 | F105: 8.894631 | G105: 11.421973 | H105: 0.450474
...

Sheet Payout test
A1: Payout test: our pay / no-pay decision vs radar’s, per square per day
A2: A square pays on a day if any 3-hour window that day had at least the trigger amount of rain. Columns C and D hold the wettest 3-hour window from our map and from radar.
A4: Trigger: rain in any 3 hours (mm) | B4: 10
A5: Decisions (square-days) | B5: =COUNT(C16:C14271) -> 14256
A6: Both pay (hit) | B6: =COUNTIFS(E16:E14271,1,F16:F14271,1) -> 1120
A7: Radar pays, we miss | B7: =COUNTIFS(E16:E14271,0,F16:F14271,1) -> 519
A8: We pay, radar doesn’t (false trigger) | B8: =COUNTIFS(E16:E14271,1,F16:F14271,0) -> 244
A9: Neither pays | B9: =COUNTIFS(E16:E14271,0,F16:F14271,0) -> 12373
A10: Agreement (the 94.6%) | B10: =(B6+B9)/B5 -> 0.94647868
A11: Radar events we caught (the 68%) | B11: =B6/(B6+B7) -> 0.6833435
A12: Our triggers radar didn’t confirm (the 18%) | B12: =B8/(B6+B8) -> 0.17888563
A15: Square | B15: Day | C15: Ours: wettest 3 h (mm) | D15: Radar: wettest 3 h (mm) | E15: We pay | F15: Radar pays | G15: Outcome
A16: 66 | B16: 2018-05-13 | C16: 17.200576 | D16: 18.7375 | E16: =IF(C16>=$B$4,1,0) -> 1 | F16: =IF(D16>=$B$4,1,0) -> 1 | G16: =IF(AND(E16=1,F16=1),"Both pay",IF(F16=1,"Missed",IF(E16=1,"False trigger","Neither"))) -> Both pay
A17: 67 | B17: 2018-05-13 | C17: 20.594423 | D17: 18.27375 | E17: =IF(C17>=$B$4,1,0) -> 1 | F17: =IF(D17>=$B$4,1,0) -> 1 | G17: =IF(AND(E17=1,F17=1),"Both pay",IF(F17=1,"Missed",IF(E17=1,"False trigger","Neither"))) -> Both pay
A18: 68 | B18: 2018-05-13 | C18: 20.606036 | D18: 17.495 | E18: =IF(C18>=$B$4,1,0) -> 1 | F18: =IF(D18>=$B$4,1,0) -> 1 | G18: =IF(AND(E18=1,F18=1),"Both pay",IF(F18=1,"Missed",IF(E18=1,"False trigger","Neither"))) -> Both pay
A19: 75 | B19: 2018-05-13 | C19: 2.8701768 | D19: 1.354375 | E19: =IF(C19>=$B$4,1,0) -> 0 | F19: =IF(D19>=$B$4,1,0) -> 0 | G19: =IF(AND(E19=1,F19=1),"Both pay",IF(F19=1,"Missed",IF(E19=1,"False trigger","Neither"))) -> Neither
A20: 76 | B20: 2018-05-13 | C20: 1.9465401 | D20: 1.9325 | E20: =IF(C20>=$B$4,1,0) -> 0 | F20: =IF(D20>=$B$4,1,0) -> 0 | G20: =IF(AND(E20=1,F20=1),"Both pay",IF(F20=1,"Missed",IF(E20=1,"False trigger","Neither"))) -> Neither
A21: 77 | B21: 2018-05-13 | C21: 2.3155601 | D21: 2.385625 | E21: =IF(C21>=$B$4,1,0) -> 0 | F21: =IF(D21>=$B$4,1,0) -> 0 | G21: =IF(AND(E21=1,F21=1),"Both pay",IF(F21=1,"Missed",IF(E21=1,"False trigger","Neither"))) -> Neither
A22: 81 | B22: 2018-05-13 | C22: 4.3703369 | D22: 2.991875 | E22: =IF(C22>=$B$4,1,0) -> 0 | F22: =IF(D22>=$B$4,1,0) -> 0 | G22: =IF(AND(E22=1,F22=1),"Both pay",IF(F22=1,"Missed",IF(E22=1,"False trigger","Neither"))) -> Neither
A23: 82 | B23: 2018-05-13 | C23: 5.0327869 | D23: 3.214375 | E23: =IF(C23>=$B$4,1,0) -> 0 | F23: =IF(D23>=$B$4,1,0) -> 0 | G23: =IF(AND(E23=1,F23=1),"Both pay",IF(F23=1,"Missed",IF(E23=1,"False trigger","Neither"))) -> Neither
A24: 89 | B24: 2018-05-13 | C24: 11.378481 | D24: 19.330625 | E24: =IF(C24>=$B$4,1,0) -> 1 | F24: =IF(D24>=$B$4,1,0) -> 1 | G24: =IF(AND(E24=1,F24=1),"Both pay",IF(F24=1,"Missed",IF(E24=1,"False trigger","Neither"))) -> Both pay
A25: 90 | B25: 2018-05-13 | C25: 11.320932 | D25: 29.944375 | E25: =IF(C25>=$B$4,1,0) -> 1 | F25: =IF(D25>=$B$4,1,0) -> 1 | G25: =IF(AND(E25=1,F25=1),"Both pay",IF(F25=1,"Missed",IF(E25=1,"False trigger","Neither"))) -> Both pay
A26: 91 | B26: 2018-05-13 | C26: 11.138785 | D26: 35.549375 | E26: =IF(C26>=$B$4,1,0) -> 1 | F26: =IF(D26>=$B$4,1,0) -> 1 | G26: =IF(AND(E26=1,F26=1),"Both pay",IF(F26=1,"Missed",IF(E26=1,"False trigger","Neither"))) -> Both pay
A27: 92 | B27: 2018-05-13 | C27: 8.1182566 | D27: 35.805625 | E27: =IF(C27>=$B$4,1,0) -> 0 | F27: =IF(D27>=$B$4,1,0) -> 1 | G27: =IF(AND(E27=1,F27=1),"Both pay",IF(F27=1,"Missed",IF(E27=1,"False trigger","Neither"))) -> Missed
... A14271: 2669 | B14271: 2018-05-20 | C14271: 0.11317072 | D14271: 0.03375 | E14271: =IF(C14271>=$B$4,1,0) -> 0 | F14271: =IF(D14271>=$B$4,1,0) -> 0 | G14271: =IF(AND(E14271=1,F14271=1),"Both pay",IF(F14271=1,"Missed",IF(E14271=1,"False trigger","Neither"))) -> Neither

Sheet India daily
A1: City | B1: Station | C1: Date | D1: Year | E1: Rain (mm) | F1: Highest temperature (°C)
A2: Ahmedabad | B2: 42647099999 | C2: 2000-01-01 | D2: 2000 | E2: 0 | F2: 29.611111
A3: Ahmedabad | B3: 42647099999 | C3: 2000-01-02 | D3: 2000 | E3: 0 | F3: 30
A4: Ahmedabad | B4: 42647099999 | C4: 2000-01-03 | D4: 2000 | E4: 0 | F4: 30.277778
A5: Ahmedabad | B5: 42647099999 | C5: 2000-01-04 | D5: 2000 | E5: 0 | F5: 30.222222
A6: Ahmedabad | B6: 42647099999 | C6: 2000-01-05 | D6: 2000 | E6: 0 | F6: 29.388889
A7: Ahmedabad | B7: 42647099999 | C7: 2000-01-06 | D7: 2000 | E7: 0 | F7: 30.388889
A8: Ahmedabad | B8: 42647099999 | C8: 2000-01-07 | D8: 2000 | E8: 0 | F8: 30.277778
A9: Ahmedabad | B9: 42647099999 | C9: 2000-01-08 | D9: 2000 | E9: 0 | F9: 31.777778
A10: Ahmedabad | B10: 42647099999 | C10: 2000-01-09 | D10: 2000 | E10: 0 | F10: 32.222222
A11: Ahmedabad | B11: 42647099999 | C11: 2000-01-10 | D11: 2000 | E11: 0 | F11: 31.722222
A12: Ahmedabad | B12: 42647099999 | C12: 2000-01-11 | D12: 2000 | E12: 0 | F12: 32.611111
A13: Ahmedabad | B13: 42647099999 | C13: 2000-01-12 | D13: 2000 | E13: 0 | F13: 28
... A126: Ahmedabad | B126: 42647099999 | C126: 2000-05-05 | D126: 2000 | E126: 0 | F126: 41.722222
A127: Ahmedabad | B127: 42647099999 | C127: 2000-05-06 | D127: 2000 | F127: 41.388889
A128: Ahmedabad | B128: 42647099999 | C128: 2000-05-07 | D128: 2000 | E128: 0 | F128: 41
A129: Ahmedabad | B129: 42647099999 | C129: 2000-05-08 | D129: 2000 | E129: 0 | F129: 38.388889
A130: Ahmedabad | B130: 42647099999 | C130: 2000-05-09 | D130: 2000 | E130: 0 | F130: 40.777778
A131: Ahmedabad | B131: 42647099999 | C131: 2000-05-10 | D131: 2000 | E131: 0 | F131: 38.277778
A132: Ahmedabad | B132: 42647099999 | C132: 2000-05-11 | D132: 2000 | E132: 0 | F132: 38
A133: Ahmedabad | B133: 42647099999 | C133: 2000-05-12 | D133: 2000 | E133: 0 | F133: 37
A134: Ahmedabad | B134: 42647099999 | C134: 2000-05-13 | D134: 2000 | E134: 0 | F134: 39.722222
A135: Ahmedabad | B135: 42647099999 | C135: 2000-05-14 | D135: 2000 | E135: 0 | F135: 39.5
A136: Ahmedabad | B136: 42647099999 | C136: 2000-05-15 | D136: 2000 | E136: 0 | F136: 38.777778
A137: Ahmedabad | B137: 42647099999 | C137: 2000-05-16 | D137: 2000 | E137: 0 | F137: 38.611111
A138: Ahmedabad | B138: 42647099999 | C138: 2000-05-17 | D138: 2000 | E138: 0 | F138: 37.777778
A139: Ahmedabad | B139: 42647099999 | C139: 2000-05-18 | D139: 2000 | E139: 0 | F139: 37.222222
A140: Ahmedabad | B140: 42647099999 | C140: 2000-05-19 | D140: 2000 | F140: 40.388889
A141: Ahmedabad | B141: 42647099999 | C141: 2000-05-20 | D141: 2000 | E141: 72.898 | F141: 36.722222
A142: Ahmedabad | B142: 42647099999 | C142: 2000-05-21 | D142: 2000 | E142: 0 | F142: 40.277778
A143: Ahmedabad | B143: 42647099999 | C143: 2000-05-22 | D143: 2000 | E143: 0 | F143: 40.611111
A144: Ahmedabad | B144: 42647099999 | C144: 2000-05-23 | D144: 2000 | E144: 0 | F144: 40
A145: Ahmedabad | B145: 42647099999 | C145: 2000-05-24 | D145: 2000 | E145: 0 | F145: 40.277778
A146: Ahmedabad | B146: 42647099999 | C146: 2000-05-25 | D146: 2000 | E146: 0 | F146: 40.722222
A147: Ahmedabad | B147: 42647099999 | C147: 2000-05-26 | D147: 2000 | E147: 0 | F147: 40.888889
A148: Ahmedabad | B148: 42647099999 | C148: 2000-05-27 | D148: 2000 | E148: 0 | F148: 40.388889
A149: Ahmedabad | B149: 42647099999 | C149: 2000-05-28 | D149: 2000 | E149: 0 | F149: 39.888889
A150: Ahmedabad | B150: 42647099999 | C150: 2000-05-29 | D150: 2000 | E150: 0 | F150: 38.777778
A151: Ahmedabad | B151: 42647099999 | C151: 2000-05-30 | D151: 2000 | E151: 0 | F151: 38.5
A152: Ahmedabad | B152: 42647099999 | C152: 2000-05-31 | D152: 2000 | E152: 0 | F152: 39
...

Sheet Prices
A1: Prices from 25 years of IMD records
A2: Count the trigger days in each year, cap them, average them, then price = average days paid × payout ÷ payout share ÷ 12.
A4: Payout per trigger day (₹) | B4: 300
A5: Target payout share (claims ÷ premiums) | B5: 0.6 | C5: The other 40% pays the insurer, reinsurance, Jio’s fees and running costs.
A6: Price floor for Kavach Basic (₹ a month) | B6: 29 | C6: ₹29 comes from our design rule: a typical location triggers about 0.7 days a year (0.7 × ₹300 ÷ 0.6 ÷ 12 = ₹29).
A8: Product | B8: City | C8: Weather (Rain or Heat) | D8: Trigger (mm a day, or °C) | E8: Most days paid a year | F8: Price floor applies? | G8: Avg trigger days a year | H8: Avg days paid a year | I8: Claims per person a year (₹) | J8: Cost price per month (₹) | K8: Price charged per month (₹)
A9: Kavach Plus · Mumbai riders | B9: Mumbai | C9: Rain | D9: 64.5 | E9: 5 | F9: No | G9: =AVERAGE(B17:B41) -> 11.88 | H9: =AVERAGE(C17:C41) -> 5 | I9: =H9*$B$4 -> 1500 | J9: =I9/$B$5/12 -> 208.33333 | K9: =IF(F9="Yes",MAX(J9,$B$6),J9) -> 208.33333
A10: Kavach Plus · 3-day cap | B10: Mumbai | C10: Rain | D10: 64.5 | E10: 3 | F10: No | G10: =AVERAGE(D17:D41) -> 11.88 | H10: =AVERAGE(E17:E41) -> 3 | I10: =H10*$B$4 -> 900 | J10: =I10/$B$5/12 -> 125 | K10: =IF(F10="Yes",MAX(J10,$B$6),J10) -> 125
A11: Kavach Basic · Mumbai | B11: Mumbai | C11: Rain | D11: 204.5 | E11: 5 | F11: Yes | G11: =AVERAGE(F17:F41) -> 1.08 | H11: =AVERAGE(G17:G41) -> 1.08 | I11: =H11*$B$4 -> 324 | J11: =I11/$B$5/12 -> 45 | K11: =IF(F11="Yes",MAX(J11,$B$6),J11) -> 45
A12: Kavach Basic · Nagpur heat | B12: Nagpur | C12: Heat | D12: 47 | E12: 5 | F12: Yes | G12: =AVERAGE(H17:H41) -> 2.2 | H12: =AVERAGE(I17:I41) -> 1.24 | I12: =H12*$B$4 -> 372 | J12: =I12/$B$5/12 -> 51.666667 | K12: =IF(F12="Yes",MAX(J12,$B$6),J12) -> 51.666667
A13: Kavach Basic · Ahmedabad heat | B13: Ahmedabad | C13: Heat | D13: 47 | E13: 5 | F13: Yes | G13: =AVERAGE(J17:J41) -> 0.72 | H13: =AVERAGE(K17:K41) -> 0.64 | I13: =H13*$B$4 -> 192 | J13: =I13/$B$5/12 -> 26.666667 | K13: =IF(F13="Yes",MAX(J13,$B$6),J13) -> 29
A15: Trigger days and days paid, year by year
A16: Year | B16: Kavach Plus · Mumbai riders: trigger days | C16: days paid | D16: Kavach Plus · 3-day cap: trigger days | E16: days paid | F16: Kavach Basic · Mumbai: trigger days | G16: days paid | H16: Kavach Basic · Nagpur heat: trigger days | I16: days paid | J16: Kavach Basic · Ahmedabad heat: trigger days | K16: days paid
A17: 2000 | B17: =IF($C$9="Rain",COUNTIFS('India daily'!$A$2:$A$27104,$B$9,'India daily'!$D$2:$D$27104,VALUE($A17),'India daily'!$E$2:$E$27104,">="&$D$9),COUNTIFS('India daily'!$A$2:$A$27104,$B$9,'India daily'!$D$2:$D$27104,VALUE($A17),'India daily'!$F$2:$F$27104,">="&$D$9)) -> 9 | C17: =MIN(B17,$E$9) -> 5 | D17: =IF($C$10="Rain",COUNTIFS('India daily'!$A$2:$A$27104,$B$10,'India daily'!$D$2:$D$27104,VALUE($A17),'India daily'!$E$2:$E$27104,">="&$D$10),COUNTIFS('India daily'!$A$2:$A$27104,$B$10,'India daily'!$D$2:$D$27104,VALUE($A17),'India daily'!$F$2:$F$27104,">="&$D$10)) -> 9 | E17: =MIN(D17,$E$10) -> 3 | F17: =IF($C$11="Rain",COUNTIFS('India daily'!$A$2:$A$27104,$B$11,'India daily'!$D$2:$D$27104,VALUE($A17),'India daily'!$E$2:$E$27104,">="&$D$11),COUNTIFS('India daily'!$A$2:$A$27104,$B$11,'India daily'!$D$2:$D$27104,VALUE($A17),'India daily'!$F$2:$F$27104,">="&$D$11)) -> 1 | G17: =MIN(F17,$E$11) -> 1 | H17: =IF($C$12="Rain",COUNTIFS('India daily'!$A$2:$A$27104,$B$12,'India daily'!$D$2:$D$27104,VALUE($A17),'India daily'!$E$2:$E$27104,">="&$D$12),COUNTIFS('India daily'!$A$2:$A$27104,$B$12,'India daily'!$D$2:$D$27104,VALUE($A17),'India daily'!$F$2:$F$27104,">="&$D$12)) -> 0 | I17: =MIN(H17,$E$12) -> 0 | J17: =IF($C$13="Rain",COUNTIFS('India daily'!$A$2:$A$27104,$B$13,'India daily'!$D$2:$D$27104,VALUE($A17),'India daily'!$E$2:$E$27104,">="&$D$13),COUNTIFS('India daily'!$A$2:$A$27104,$B$13,'India daily'!$D$2:$D$27104,VALUE($A17),'India daily'!$F$2:$F$27104,">="&$D$13)) -> 0 | K17: =MIN(J17,$E$13) -> 0
A18: 2001 | B18: =IF($C$9="Rain",COUNTIFS('India daily'!$A$2:$A$27104,$B$9,'India daily'!$D$2:$D$27104,VALUE($A18),'India daily'!$E$2:$E$27104,">="&$D$9),COUNTIFS('India daily'!$A$2:$A$27104,$B$9,'India daily'!$D$2:$D$27104,VALUE($A18),'India daily'!$F$2:$F$27104,">="&$D$9)) -> 8 | C18: =MIN(B18,$E$9) -> 5 | D18: =IF($C$10="Rain",COUNTIFS('India daily'!$A$2:$A$27104,$B$10,'India daily'!$D$2:$D$27104,VALUE($A18),'India daily'!$E$2:$E$27104,">="&$D$10),COUNTIFS('India daily'!$A$2:$A$27104,$B$10,'India daily'!$D$2:$D$27104,VALUE($A18),'India daily'!$F$2:$F$27104,">="&$D$10)) -> 8 | E18: =MIN(D18,$E$10) -> 3 | F18: =IF($C$11="Rain",COUNTIFS('India daily'!$A$2:$A$27104,$B$11,'India daily'!$D$2:$D$27104,VALUE($A18),'India daily'!$E$2:$E$27104,">="&$D$11),COUNTIFS('India daily'!$A$2:$A$27104,$B$11,'India daily'!$D$2:$D$27104,VALUE($A18),'India daily'!$F$2:$F$27104,">="&$D$11)) -> 0 | G18: =MIN(F18,$E$11) -> 0 | H18: =IF($C$12="Rain",COUNTIFS('India daily'!$A$2:$A$27104,$B$12,'India daily'!$D$2:$D$27104,VALUE($A18),'India daily'!$E$2:$E$27104,">="&$D$12),COUNTIFS('India daily'!$A$2:$A$27104,$B$12,'India daily'!$D$2:$D$27104,VALUE($A18),'India daily'!$F$2:$F$27104,">="&$D$12)) -> 0 | I18: =MIN(H18,$E$12) -> 0 | J18: =IF($C$13="Rain",COUNTIFS('India daily'!$A$2:$A$27104,$B$13,'India daily'!$D$2:$D$27104,VALUE($A18),'India daily'!$E$2:$E$27104,">="&$D$13),COUNTIFS('India daily'!$A$2:$A$27104,$B$13,'India daily'!$D$2:$D$27104,VALUE($A18),'India daily'!$F$2:$F$27104,">="&$D$13)) -> 0 | K18: =MIN(J18,$E$13) -> 0
A19: 2002 | B19: =IF($C$9="Rain",COUNTIFS('India daily'!$A$2:$A$27104,$B$9,'India daily'!$D$2:$D$27104,VALUE($A19),'India daily'!$E$2:$E$27104,">="&$D$9),COUNTIFS('India daily'!$A$2:$A$27104,$B$9,'India daily'!$D$2:$D$27104,VALUE($A19),'India daily'!$F$2:$F$27104,">="&$D$9)) -> 6 | C19: =MIN(B19,$E$9) -> 5 | D19: =IF($C$10="Rain",COUNTIFS('India daily'!$A$2:$A$27104,$B$10,'India daily'!$D$2:$D$27104,VALUE($A19),'India daily'!$E$2:$E$27104,">="&$D$10),COUNTIFS('India daily'!$A$2:$A$27104,$B$10,'India daily'!$D$2:$D$27104,VALUE($A19),'India daily'!$F$2:$F$27104,">="&$D$10)) -> 6 | E19: =MIN(D19,$E$10) -> 3 | F19: =IF($C$11="Rain",COUNTIFS('India daily'!$A$2:$A$27104,$B$11,'India daily'!$D$2:$D$27104,VALUE($A19),'India daily'!$E$2:$E$27104,">="&$D$11),COUNTIFS('India daily'!$A$2:$A$27104,$B$11,'India daily'!$D$2:$D$27104,VALUE($A19),'India daily'!$F$2:$F$27104,">="&$D$11)) -> 0 | G19: =MIN(F19,$E$11) -> 0 | H19: =IF($C$12="Rain",COUNTIFS('India daily'!$A$2:$A$27104,$B$12,'India daily'!$D$2:$D$27104,VALUE($A19),'India daily'!$E$2:$E$27104,">="&$D$12),COUNTIFS('India daily'!$A$2:$A$27104,$B$12,'India daily'!$D$2:$D$27104,VALUE($A19),'India daily'!$F$2:$F$27104,">="&$D$12)) -> 0 | I19: =MIN(H19,$E$12) -> 0 | J19: =IF($C$13="Rain",COUNTIFS('India daily'!$A$2:$A$27104,$B$13,'India daily'!$D$2:$D$27104,VALUE($A19),'India daily'!$E$2:$E$27104,">="&$D$13),COUNTIFS('India daily'!$A$2:$A$27104,$B$13,'India daily'!$D$2:$D$27104,VALUE($A19),'India daily'!$F$2:$F$27104,">="&$D$13)) -> 0 | K19: =MIN(J19,$E$13) -> 0
A20: 2003 | B20: =IF($C$9="Rain",COUNTIFS('India daily'!$A$2:$A$27104,$B$9,'India daily'!$D$2:$D$27104,VALUE($A20),'India daily'!$E$2:$E$27104,">="&$D$9),COUNTIFS('India daily'!$A$2:$A$27104,$B$9,'India daily'!$D$2:$D$27104,VALUE($A20),'India daily'!$F$2:$F$27104,">="&$D$9)) -> 10 | C20: =MIN(B20,$E$9) -> 5 | D20: =IF($C$10="Rain",COUNTIFS('India daily'!$A$2:$A$27104,$B$10,'India daily'!$D$2:$D$27104,VALUE($A20),'India daily'!$E$2:$E$27104,">="&$D$10),COUNTIFS('India daily'!$A$2:$A$27104,$B$10,'India daily'!$D$2:$D$27104,VALUE($A20),'India daily'!$F$2:$F$27104,">="&$D$10)) -> 10 | E20: =MIN(D20,$E$10) -> 3 | F20: =IF($C$11="Rain",COUNTIFS('India daily'!$A$2:$A$27104,$B$11,'India daily'!$D$2:$D$27104,VALUE($A20),'India daily'!$E$2:$E$27104,">="&$D$11),COUNTIFS('India daily'!$A$2:$A$27104,$B$11,'India daily'!$D$2:$D$27104,VALUE($A20),'India daily'!$F$2:$F$27104,">="&$D$11)) -> 0 | G20: =MIN(F20,$E$11) -> 0 | H20: =IF($C$12="Rain",COUNTIFS('India daily'!$A$2:$A$27104,$B$12,'India daily'!$D$2:$D$27104,VALUE($A20),'India daily'!$E$2:$E$27104,">="&$D$12),COUNTIFS('India daily'!$A$2:$A$27104,$B$12,'India daily'!$D$2:$D$27104,VALUE($A20),'India daily'!$F$2:$F$27104,">="&$D$12)) -> 4 | I20: =MIN(H20,$E$12) -> 4 | J20: =IF($C$13="Rain",COUNTIFS('India daily'!$A$2:$A$27104,$B$13,'India daily'!$D$2:$D$27104,VALUE($A20),'India daily'!$E$2:$E$27104,">="&$D$13),COUNTIFS('India daily'!$A$2:$A$27104,$B$13,'India daily'!$D$2:$D$27104,VALUE($A20),'India daily'!$F$2:$F$27104,">="&$D$13)) -> 0 | K20: =MIN(J20,$E$13) -> 0
A21: 2004 | B21: =IF($C$9="Rain",COUNTIFS('India daily'!$A$2:$A$27104,$B$9,'India daily'!$D$2:$D$27104,VALUE($A21),'India daily'!$E$2:$E$27104,">="&$D$9),COUNTIFS('India daily'!$A$2:$A$27104,$B$9,'India daily'!$D$2:$D$27104,VALUE($A21),'India daily'!$F$2:$F$27104,">="&$D$9)) -> 10 | C21: =MIN(B21,$E$9) -> 5 | D21: =IF($C$10="Rain",COUNTIFS('India daily'!$A$2:$A$27104,$B$10,'India daily'!$D$2:$D$27104,VALUE($A21),'India daily'!$E$2:$E$27104,">="&$D$10),COUNTIFS('India daily'!$A$2:$A$27104,$B$10,'India daily'!$D$2:$D$27104,VALUE($A21),'India daily'!$F$2:$F$27104,">="&$D$10)) -> 10 | E21: =MIN(D21,$E$10) -> 3 | F21: =IF($C$11="Rain",COUNTIFS('India daily'!$A$2:$A$27104,$B$11,'India daily'!$D$2:$D$27104,VALUE($A21),'India daily'!$E$2:$E$27104,">="&$D$11),COUNTIFS('India daily'!$A$2:$A$27104,$B$11,'India daily'!$D$2:$D$27104,VALUE($A21),'India daily'!$F$2:$F$27104,">="&$D$11)) -> 0 | G21: =MIN(F21,$E$11) -> 0 | H21: =IF($C$12="Rain",COUNTIFS('India daily'!$A$2:$A$27104,$B$12,'India daily'!$D$2:$D$27104,VALUE($A21),'India daily'!$E$2:$E$27104,">="&$D$12),COUNTIFS('India daily'!$A$2:$A$27104,$B$12,'India daily'!$D$2:$D$27104,VALUE($A21),'India daily'!$F$2:$F$27104,">="&$D$12)) -> 0 | I21: =MIN(H21,$E$12) -> 0 | J21: =IF($C$13="Rain",COUNTIFS('India daily'!$A$2:$A$27104,$B$13,'India daily'!$D$2:$D$27104,VALUE($A21),'India daily'!$E$2:$E$27104,">="&$D$13),COUNTIFS('India daily'!$A$2:$A$27104,$B$13,'India daily'!$D$2:$D$27104,VALUE($A21),'India daily'!$F$2:$F$27104,">="&$D$13)) -> 0 | K21: =MIN(J21,$E$13) -> 0
A22: 2005 | B22: =IF($C$9="Rain",COUNTIFS('India daily'!$A$2:$A$27104,$B$9,'India daily'!$D$2:$D$27104,VALUE($A22),'India daily'!$E$2:$E$27104,">="&$D$9),COUNTIFS('India daily'!$A$2:$A$27104,$B$9,'India daily'!$D$2:$D$27104,VALUE($A22),'India daily'!$F$2:$F$27104,">="&$D$9)) -> 12 | C22: =MIN(B22,$E$9) -> 5 | D22: =IF($C$10="Rain",COUNTIFS('India daily'!$A$2:$A$27104,$B$10,'India daily'!$D$2:$D$27104,VALUE($A22),'India daily'!$E$2:$E$27104,">="&$D$10),COUNTIFS('India daily'!$A$2:$A$27104,$B$10,'India daily'!$D$2:$D$27104,VALUE($A22),'India daily'!$F$2:$F$27104,">="&$D$10)) -> 12 | E22: =MIN(D22,$E$10) -> 3 | F22: =IF($C$11="Rain",COUNTIFS('India daily'!$A$2:$A$27104,$B$11,'India daily'!$D$2:$D$27104,VALUE($A22),'India daily'!$E$2:$E$27104,">="&$D$11),COUNTIFS('India daily'!$A$2:$A$27104,$B$11,'India daily'!$D$2:$D$27104,VALUE($A22),'India daily'!$F$2:$F$27104,">="&$D$11)) -> 3 | G22: =MIN(F22,$E$11) -> 3 | H22: =IF($C$12="Rain",COUNTIFS('India daily'!$A$2:$A$27104,$B$12,'India daily'!$D$2:$D$27104,VALUE($A22),'India daily'!$E$2:$E$27104,">="&$D$12),COUNTIFS('India daily'!$A$2:$A$27104,$B$12,'India daily'!$D$2:$D$27104,VALUE($A22),'India daily'!$F$2:$F$27104,">="&$D$12)) -> 2 | I22: =MIN(H22,$E$12) -> 2 | J22: =IF($C$13="Rain",COUNTIFS('India daily'!$A$2:$A$27104,$B$13,'India daily'!$D$2:$D$27104,VALUE($A22),'India daily'!$E$2:$E$27104,">="&$D$13),COUNTIFS('India daily'!$A$2:$A$27104,$B$13,'India daily'!$D$2:$D$27104,VALUE($A22),'India daily'!$F$2:$F$27104,">="&$D$13)) -> 0 | K22: =MIN(J22,$E$13) -> 0
A23: 2006 | B23: =IF($C$9="Rain",COUNTIFS('India daily'!$A$2:$A$27104,$B$9,'India daily'!$D$2:$D$27104,VALUE($A23),'India daily'!$E$2:$E$27104,">="&$D$9),COUNTIFS('India daily'!$A$2:$A$27104,$B$9,'India daily'!$D$2:$D$27104,VALUE($A23),'India daily'!$F$2:$F$27104,">="&$D$9)) -> 15 | C23: =MIN(B23,$E$9) -> 5 | D23: =IF($C$10="Rain",COUNTIFS('India daily'!$A$2:$A$27104,$B$10,'India daily'!$D$2:$D$27104,VALUE($A23),'India daily'!$E$2:$E$27104,">="&$D$10),COUNTIFS('India daily'!$A$2:$A$27104,$B$10,'India daily'!$D$2:$D$27104,VALUE($A23),'India daily'!$F$2:$F$27104,">="&$D$10)) -> 15 | E23: =MIN(D23,$E$10) -> 3 | F23: =IF($C$11="Rain",COUNTIFS('India daily'!$A$2:$A$27104,$B$11,'India daily'!$D$2:$D$27104,VALUE($A23),'India daily'!$E$2:$E$27104,">="&$D$11),COUNTIFS('India daily'!$A$2:$A$27104,$B$11,'India daily'!$D$2:$D$27104,VALUE($A23),'India daily'!$F$2:$F$27104,">="&$D$11)) -> 2 | G23: =MIN(F23,$E$11) -> 2 | H23: =IF($C$12="Rain",COUNTIFS('India daily'!$A$2:$A$27104,$B$12,'India daily'!$D$2:$D$27104,VALUE($A23),'India daily'!$E$2:$E$27104,">="&$D$12),COUNTIFS('India daily'!$A$2:$A$27104,$B$12,'India daily'!$D$2:$D$27104,VALUE($A23),'India daily'!$F$2:$F$27104,">="&$D$12)) -> 0 | I23: =MIN(H23,$E$12) -> 0 | J23: =IF($C$13="Rain",COUNTIFS('India daily'!$A$2:$A$27104,$B$13,'India daily'!$D$2:$D$27104,VALUE($A23),'India daily'!$E$2:$E$27104,">="&$D$13),COUNTIFS('India daily'!$A$2:$A$27104,$B$13,'India daily'!$D$2:$D$27104,VALUE($A23),'India daily'!$F$2:$F$27104,">="&$D$13)) -> 0 | K23: =MIN(J23,$E$13) -> 0
A24: 2007 | B24: =IF($C$9="Rain",COUNTIFS('India daily'!$A$2:$A$27104,$B$9,'India daily'!$D$2:$D$27104,VALUE($A24),'India daily'!$E$2:$E$27104,">="&$D$9),COUNTIFS('India daily'!$A$2:$A$27104,$B$9,'India daily'!$D$2:$D$27104,VALUE($A24),'India daily'!$F$2:$F$27104,">="&$D$9)) -> 10 | C24: =MIN(B24,$E$9) -> 5 | D24: =IF($C$10="Rain",COUNTIFS('India daily'!$A$2:$A$27104,$B$10,'India daily'!$D$2:$D$27104,VALUE($A24),'India daily'!$E$2:$E$27104,">="&$D$10),COUNTIFS('India daily'!$A$2:$A$27104,$B$10,'India daily'!$D$2:$D$27104,VALUE($A24),'India daily'!$F$2:$F$27104,">="&$D$10)) -> 10 | E24: =MIN(D24,$E$10) -> 3 | F24: =IF($C$11="Rain",COUNTIFS('India daily'!$A$2:$A$27104,$B$11,'India daily'!$D$2:$D$27104,VALUE($A24),'India daily'!$E$2:$E$27104,">="&$D$11),COUNTIFS('India daily'!$A$2:$A$27104,$B$11,'India daily'!$D$2:$D$27104,VALUE($A24),'India daily'!$F$2:$F$27104,">="&$D$11)) -> 2 | G24: =MIN(F24,$E$11) -> 2 | H24: =IF($C$12="Rain",COUNTIFS('India daily'!$A$2:$A$27104,$B$12,'India daily'!$D$2:$D$27104,VALUE($A24),'India daily'!$E$2:$E$27104,">="&$D$12),COUNTIFS('India daily'!$A$2:$A$27104,$B$12,'India daily'!$D$2:$D$27104,VALUE($A24),'India daily'!$F$2:$F$27104,">="&$D$12)) -> 0 | I24: =MIN(H24,$E$12) -> 0 | J24: =IF($C$13="Rain",COUNTIFS('India daily'!$A$2:$A$27104,$B$13,'India daily'!$D$2:$D$27104,VALUE($A24),'India daily'!$E$2:$E$27104,">="&$D$13),COUNTIFS('India daily'!$A$2:$A$27104,$B$13,'India daily'!$D$2:$D$27104,VALUE($A24),'India daily'!$F$2:$F$27104,">="&$D$13)) -> 0 | K24: =MIN(J24,$E$13) -> 0
A25: 2008 | B25: =IF($C$9="Rain",COUNTIFS('India daily'!$A$2:$A$27104,$B$9,'India daily'!$D$2:$D$27104,VALUE($A25),'India daily'!$E$2:$E$27104,">="&$D$9),COUNTIFS('India daily'!$A$2:$A$27104,$B$9,'India daily'!$D$2:$D$27104,VALUE($A25),'India daily'!$F$2:$F$27104,">="&$D$9)) -> 14 | C25: =MIN(B25,$E$9) -> 5 | D25: =IF($C$10="Rain",COUNTIFS('India daily'!$A$2:$A$27104,$B$10,'India daily'!$D$2:$D$27104,VALUE($A25),'India daily'!$E$2:$E$27104,">="&$D$10),COUNTIFS('India daily'!$A$2:$A$27104,$B$10,'India daily'!$D$2:$D$27104,VALUE($A25),'India daily'!$F$2:$F$27104,">="&$D$10)) -> 14 | E25: =MIN(D25,$E$10) -> 3 | F25: =IF($C$11="Rain",COUNTIFS('India daily'!$A$2:$A$27104,$B$11,'India daily'!$D$2:$D$27104,VALUE($A25),'India daily'!$E$2:$E$27104,">="&$D$11),COUNTIFS('India daily'!$A$2:$A$27104,$B$11,'India daily'!$D$2:$D$27104,VALUE($A25),'India daily'!$F$2:$F$27104,">="&$D$11)) -> 0 | G25: =MIN(F25,$E$11) -> 0 | H25: =IF($C$12="Rain",COUNTIFS('India daily'!$A$2:$A$27104,$B$12,'India daily'!$D$2:$D$27104,VALUE($A25),'India daily'!$E$2:$E$27104,">="&$D$12),COUNTIFS('India daily'!$A$2:$A$27104,$B$12,'India daily'!$D$2:$D$27104,VALUE($A25),'India daily'!$F$2:$F$27104,">="&$D$12)) -> 0 | I25: =MIN(H25,$E$12) -> 0 | J25: =IF($C$13="Rain",COUNTIFS('India daily'!$A$2:$A$27104,$B$13,'India daily'!$D$2:$D$27104,VALUE($A25),'India daily'!$E$2:$E$27104,">="&$D$13),COUNTIFS('India daily'!$A$2:$A$27104,$B$13,'India daily'!$D$2:$D$27104,VALUE($A25),'India daily'!$F$2:$F$27104,">="&$D$13)) -> 0 | K25: =MIN(J25,$E$13) -> 0
A26: 2009 | B26: =IF($C$9="Rain",COUNTIFS('India daily'!$A$2:$A$27104,$B$9,'India daily'!$D$2:$D$27104,VALUE($A26),'India daily'!$E$2:$E$27104,">="&$D$9),COUNTIFS('India daily'!$A$2:$A$27104,$B$9,'India daily'!$D$2:$D$27104,VALUE($A26),'India daily'!$F$2:$F$27104,">="&$D$9)) -> 8 | C26: =MIN(B26,$E$9) -> 5 | D26: =IF($C$10="Rain",COUNTIFS('India daily'!$A$2:$A$27104,$B$10,'India daily'!$D$2:$D$27104,VALUE($A26),'India daily'!$E$2:$E$27104,">="&$D$10),COUNTIFS('India daily'!$A$2:$A$27104,$B$10,'India daily'!$D$2:$D$27104,VALUE($A26),'India daily'!$F$2:$F$27104,">="&$D$10)) -> 8 | E26: =MIN(D26,$E$10) -> 3 | F26: =IF($C$11="Rain",COUNTIFS('India daily'!$A$2:$A$27104,$B$11,'India daily'!$D$2:$D$27104,VALUE($A26),'India daily'!$E$2:$E$27104,">="&$D$11),COUNTIFS('India daily'!$A$2:$A$27104,$B$11,'India daily'!$D$2:$D$27104,VALUE($A26),'India daily'!$F$2:$F$27104,">="&$D$11)) -> 2 | G26: =MIN(F26,$E$11) -> 2 | H26: =IF($C$12="Rain",COUNTIFS('India daily'!$A$2:$A$27104,$B$12,'India daily'!$D$2:$D$27104,VALUE($A26),'India daily'!$E$2:$E$27104,">="&$D$12),COUNTIFS('India daily'!$A$2:$A$27104,$B$12,'India daily'!$D$2:$D$27104,VALUE($A26),'India daily'!$F$2:$F$27104,">="&$D$12)) -> 1 | I26: =MIN(H26,$E$12) -> 1 | J26: =IF($C$13="Rain",COUNTIFS('India daily'!$A$2:$A$27104,$B$13,'India daily'!$D$2:$D$27104,VALUE($A26),'India daily'!$E$2:$E$27104,">="&$D$13),COUNTIFS('India daily'!$A$2:$A$27104,$B$13,'India daily'!$D$2:$D$27104,VALUE($A26),'India daily'!$F$2:$F$27104,">="&$D$13)) -> 0 | K26: =MIN(J26,$E$13) -> 0
A27: 2010 | B27: =IF($C$9="Rain",COUNTIFS('India daily'!$A$2:$A$27104,$B$9,'India daily'!$D$2:$D$27104,VALUE($A27),'India daily'!$E$2:$E$27104,">="&$D$9),COUNTIFS('India daily'!$A$2:$A$27104,$B$9,'India daily'!$D$2:$D$27104,VALUE($A27),'India daily'!$F$2:$F$27104,">="&$D$9)) -> 19 | C27: =MIN(B27,$E$9) -> 5 | D27: =IF($C$10="Rain",COUNTIFS('India daily'!$A$2:$A$27104,$B$10,'India daily'!$D$2:$D$27104,VALUE($A27),'India daily'!$E$2:$E$27104,">="&$D$10),COUNTIFS('India daily'!$A$2:$A$27104,$B$10,'India daily'!$D$2:$D$27104,VALUE($A27),'India daily'!$F$2:$F$27104,">="&$D$10)) -> 19 | E27: =MIN(D27,$E$10) -> 3 | F27: =IF($C$11="Rain",COUNTIFS('India daily'!$A$2:$A$27104,$B$11,'India daily'!$D$2:$D$27104,VALUE($A27),'India daily'!$E$2:$E$27104,">="&$D$11),COUNTIFS('India daily'!$A$2:$A$27104,$B$11,'India daily'!$D$2:$D$27104,VALUE($A27),'India daily'!$F$2:$F$27104,">="&$D$11)) -> 0 | G27: =MIN(F27,$E$11) -> 0 | H27: =IF($C$12="Rain",COUNTIFS('India daily'!$A$2:$A$27104,$B$12,'India daily'!$D$2:$D$27104,VALUE($A27),'India daily'!$E$2:$E$27104,">="&$D$12),COUNTIFS('India daily'!$A$2:$A$27104,$B$12,'India daily'!$D$2:$D$27104,VALUE($A27),'India daily'!$F$2:$F$27104,">="&$D$12)) -> 2 | I27: =MIN(H27,$E$12) -> 2 | J27: =IF($C$13="Rain",COUNTIFS('India daily'!$A$2:$A$27104,$B$13,'India daily'!$D$2:$D$27104,VALUE($A27),'India daily'!$E$2:$E$27104,">="&$D$13),COUNTIFS('India daily'!$A$2:$A$27104,$B$13,'India daily'!$D$2:$D$27104,VALUE($A27),'India daily'!$F$2:$F$27104,">="&$D$13)) -> 1 | K27: =MIN(J27,$E$13) -> 1
A28: 2011 | B28: =IF($C$9="Rain",COUNTIFS('India daily'!$A$2:$A$27104,$B$9,'India daily'!$D$2:$D$27104,VALUE($A28),'India daily'!$E$2:$E$27104,">="&$D$9),COUNTIFS('India daily'!$A$2:$A$27104,$B$9,'India daily'!$D$2:$D$27104,VALUE($A28),'India daily'!$F$2:$F$27104,">="&$D$9)) -> 15 | C28: =MIN(B28,$E$9) -> 5 | D28: =IF($C$10="Rain",COUNTIFS('India daily'!$A$2:$A$27104,$B$10,'India daily'!$D$2:$D$27104,VALUE($A28),'India daily'!$E$2:$E$27104,">="&$D$10),COUNTIFS('India daily'!$A$2:$A$27104,$B$10,'India daily'!$D$2:$D$27104,VALUE($A28),'India daily'!$F$2:$F$27104,">="&$D$10)) -> 15 | E28: =MIN(D28,$E$10) -> 3 | F28: =IF($C$11="Rain",COUNTIFS('India daily'!$A$2:$A$27104,$B$11,'India daily'!$D$2:$D$27104,VALUE($A28),'India daily'!$E$2:$E$27104,">="&$D$11),COUNTIFS('India daily'!$A$2:$A$27104,$B$11,'India daily'!$D$2:$D$27104,VALUE($A28),'India daily'!$F$2:$F$27104,">="&$D$11)) -> 1 | G28: =MIN(F28,$E$11) -> 1 | H28: =IF($C$12="Rain",COUNTIFS('India daily'!$A$2:$A$27104,$B$12,'India daily'!$D$2:$D$27104,VALUE($A28),'India daily'!$E$2:$E$27104,">="&$D$12),COUNTIFS('India daily'!$A$2:$A$27104,$B$12,'India daily'!$D$2:$D$27104,VALUE($A28),'India daily'!$F$2:$F$27104,">="&$D$12)) -> 0 | I28: =MIN(H28,$E$12) -> 0 | J28: =IF($C$13="Rain",COUNTIFS('India daily'!$A$2:$A$27104,$B$13,'India daily'!$D$2:$D$27104,VALUE($A28),'India daily'!$E$2:$E$27104,">="&$D$13),COUNTIFS('India daily'!$A$2:$A$27104,$B$13,'India daily'!$D$2:$D$27104,VALUE($A28),'India daily'!$F$2:$F$27104,">="&$D$13)) -> 0 | K28: =MIN(J28,$E$13) -> 0
... A41: 2024 | B41: =IF($C$9="Rain",COUNTIFS('India daily'!$A$2:$A$27104,$B$9,'India daily'!$D$2:$D$27104,VALUE($A41),'India daily'!$E$2:$E$27104,">="&$D$9),COUNTIFS('India daily'!$A$2:$A$27104,$B$9,'India daily'!$D$2:$D$27104,VALUE($A41),'India daily'!$F$2:$F$27104,">="&$D$9)) -> 18 | C41: =MIN(B41,$E$9) -> 5 | D41: =IF($C$10="Rain",COUNTIFS('India daily'!$A$2:$A$27104,$B$10,'India daily'!$D$2:$D$27104,VALUE($A41),'India daily'!$E$2:$E$27104,">="&$D$10),COUNTIFS('India daily'!$A$2:$A$27104,$B$10,'India daily'!$D$2:$D$27104,VALUE($A41),'India daily'!$F$2:$F$27104,">="&$D$10)) -> 18 | E41: =MIN(D41,$E$10) -> 3 | F41: =IF($C$11="Rain",COUNTIFS('India daily'!$A$2:$A$27104,$B$11,'India daily'!$D$2:$D$27104,VALUE($A41),'India daily'!$E$2:$E$27104,">="&$D$11),COUNTIFS('India daily'!$A$2:$A$27104,$B$11,'India daily'!$D$2:$D$27104,VALUE($A41),'India daily'!$F$2:$F$27104,">="&$D$11)) -> 1 | G41: =MIN(F41,$E$11) -> 1 | H41: =IF($C$12="Rain",COUNTIFS('India daily'!$A$2:$A$27104,$B$12,'India daily'!$D$2:$D$27104,VALUE($A41),'India daily'!$E$2:$E$27104,">="&$D$12),COUNTIFS('India daily'!$A$2:$A$27104,$B$12,'India daily'!$D$2:$D$27104,VALUE($A41),'India daily'!$F$2:$F$27104,">="&$D$12)) -> 0 | I41: =MIN(H41,$E$12) -> 0 | J41: =IF($C$13="Rain",COUNTIFS('India daily'!$A$2:$A$27104,$B$13,'India daily'!$D$2:$D$27104,VALUE($A41),'India daily'!$E$2:$E$27104,">="&$D$13),COUNTIFS('India daily'!$A$2:$A$27104,$B$13,'India daily'!$D$2:$D$27104,VALUE($A41),'India daily'!$F$2:$F$27104,">="&$D$13)) -> 0 | K41: =MIN(J41,$E$13) -> 0

Sheet Stress test
A1: Stress test: every year replayed
A2: Claims ÷ premiums for each year, if we had sold the product at its cost price. Above 100% the year loses money and reinsurance pays the difference.
A4: Product | B4: Premium per person a year (₹) | C4: Worst claims ÷ premiums | D4: Years above 100% | E4: Most trigger days in one year | F4: Year it happened
A5: =Prices!A9 -> Kavach Plus · Mumbai riders | B5: =Prices!J9*12 -> 2500 | C5: =MAX(B14:B38) -> 0.6 | D5: =COUNTIF(B14:B38,">1") -> 0 | E5: =MAX(Prices!B17:B41) -> 19 | F5: =INDEX(Prices!A17:A41,MATCH(E5,Prices!B17:B41,0)) -> 2010
A6: =Prices!A10 -> Kavach Plus · 3-day cap | B6: =Prices!J10*12 -> 1500 | C6: =MAX(C14:C38) -> 0.6 | D6: =COUNTIF(C14:C38,">1") -> 0 | E6: =MAX(Prices!D17:D41) -> 19 | F6: =INDEX(Prices!A17:A41,MATCH(E6,Prices!D17:D41,0)) -> 2010
A7: =Prices!A11 -> Kavach Basic · Mumbai | B7: =Prices!J11*12 -> 540 | C7: =MAX(D14:D38) -> 2.2222222 | D7: =COUNTIF(D14:D38,">1") -> 7 | E7: =MAX(Prices!F17:F41) -> 4 | F7: =INDEX(Prices!A17:A41,MATCH(E7,Prices!F17:F41,0)) -> 2019
A8: =Prices!A12 -> Kavach Basic · Nagpur heat | B8: =Prices!J12*12 -> 620 | C8: =MAX(E14:E38) -> 2.4193548 | D8: =COUNTIF(E14:E38,">1") -> 5 | E8: =MAX(Prices!H17:H41) -> 14 | F8: =INDEX(Prices!A17:A41,MATCH(E8,Prices!H17:H41,0)) -> 2013
A9: =Prices!A13 -> Kavach Basic · Ahmedabad heat | B9: =Prices!J13*12 -> 320 | C9: =MAX(F14:F38) -> 4.6875 | D9: =COUNTIF(F14:F38,">1") -> 4 | E9: =MAX(Prices!J17:J41) -> 7 | F9: =INDEX(Prices!A17:A41,MATCH(E9,Prices!J17:J41,0)) -> 2018
A12: Claims ÷ premiums, year by year
A13: Year | B13: Kavach Plus · Mumbai riders | C13: Kavach Plus · 3-day cap | D13: Kavach Basic · Mumbai | E13: Kavach Basic · Nagpur heat | F13: Kavach Basic · Ahmedabad heat
A14: 2000 | B14: =IF($B$5>0,Prices!C17*Prices!$B$4/$B$5,0) -> 0.6 | C14: =IF($B$6>0,Prices!E17*Prices!$B$4/$B$6,0) -> 0.6 | D14: =IF($B$7>0,Prices!G17*Prices!$B$4/$B$7,0) -> 0.55555556 | E14: =IF($B$8>0,Prices!I17*Prices!$B$4/$B$8,0) -> 0 | F14: =IF($B$9>0,Prices!K17*Prices!$B$4/$B$9,0) -> 0
A15: 2001 | B15: =IF($B$5>0,Prices!C18*Prices!$B$4/$B$5,0) -> 0.6 | C15: =IF($B$6>0,Prices!E18*Prices!$B$4/$B$6,0) -> 0.6 | D15: =IF($B$7>0,Prices!G18*Prices!$B$4/$B$7,0) -> 0 | E15: =IF($B$8>0,Prices!I18*Prices!$B$4/$B$8,0) -> 0 | F15: =IF($B$9>0,Prices!K18*Prices!$B$4/$B$9,0) -> 0
A16: 2002 | B16: =IF($B$5>0,Prices!C19*Prices!$B$4/$B$5,0) -> 0.6 | C16: =IF($B$6>0,Prices!E19*Prices!$B$4/$B$6,0) -> 0.6 | D16: =IF($B$7>0,Prices!G19*Prices!$B$4/$B$7,0) -> 0 | E16: =IF($B$8>0,Prices!I19*Prices!$B$4/$B$8,0) -> 0 | F16: =IF($B$9>0,Prices!K19*Prices!$B$4/$B$9,0) -> 0
A17: 2003 | B17: =IF($B$5>0,Prices!C20*Prices!$B$4/$B$5,0) -> 0.6 | C17: =IF($B$6>0,Prices!E20*Prices!$B$4/$B$6,0) -> 0.6 | D17: =IF($B$7>0,Prices!G20*Prices!$B$4/$B$7,0) -> 0 | E17: =IF($B$8>0,Prices!I20*Prices!$B$4/$B$8,0) -> 1.9354839 | F17: =IF($B$9>0,Prices!K20*Prices!$B$4/$B$9,0) -> 0
A18: 2004 | B18: =IF($B$5>0,Prices!C21*Prices!$B$4/$B$5,0) -> 0.6 | C18: =IF($B$6>0,Prices!E21*Prices!$B$4/$B$6,0) -> 0.6 | D18: =IF($B$7>0,Prices!G21*Prices!$B$4/$B$7,0) -> 0 | E18: =IF($B$8>0,Prices!I21*Prices!$B$4/$B$8,0) -> 0 | F18: =IF($B$9>0,Prices!K21*Prices!$B$4/$B$9,0) -> 0
A19: 2005 | B19: =IF($B$5>0,Prices!C22*Prices!$B$4/$B$5,0) -> 0.6 | C19: =IF($B$6>0,Prices!E22*Prices!$B$4/$B$6,0) -> 0.6 | D19: =IF($B$7>0,Prices!G22*Prices!$B$4/$B$7,0) -> 1.6666667 | E19: =IF($B$8>0,Prices!I22*Prices!$B$4/$B$8,0) -> 0.96774194 | F19: =IF($B$9>0,Prices!K22*Prices!$B$4/$B$9,0) -> 0
A20: 2006 | B20: =IF($B$5>0,Prices!C23*Prices!$B$4/$B$5,0) -> 0.6 | C20: =IF($B$6>0,Prices!E23*Prices!$B$4/$B$6,0) -> 0.6 | D20: =IF($B$7>0,Prices!G23*Prices!$B$4/$B$7,0) -> 1.1111111 | E20: =IF($B$8>0,Prices!I23*Prices!$B$4/$B$8,0) -> 0 | F20: =IF($B$9>0,Prices!K23*Prices!$B$4/$B$9,0) -> 0
A21: 2007 | B21: =IF($B$5>0,Prices!C24*Prices!$B$4/$B$5,0) -> 0.6 | C21: =IF($B$6>0,Prices!E24*Prices!$B$4/$B$6,0) -> 0.6 | D21: =IF($B$7>0,Prices!G24*Prices!$B$4/$B$7,0) -> 1.1111111 | E21: =IF($B$8>0,Prices!I24*Prices!$B$4/$B$8,0) -> 0 | F21: =IF($B$9>0,Prices!K24*Prices!$B$4/$B$9,0) -> 0
A22: 2008 | B22: =IF($B$5>0,Prices!C25*Prices!$B$4/$B$5,0) -> 0.6 | C22: =IF($B$6>0,Prices!E25*Prices!$B$4/$B$6,0) -> 0.6 | D22: =IF($B$7>0,Prices!G25*Prices!$B$4/$B$7,0) -> 0 | E22: =IF($B$8>0,Prices!I25*Prices!$B$4/$B$8,0) -> 0 | F22: =IF($B$9>0,Prices!K25*Prices!$B$4/$B$9,0) -> 0
A23: 2009 | B23: =IF($B$5>0,Prices!C26*Prices!$B$4/$B$5,0) -> 0.6 | C23: =IF($B$6>0,Prices!E26*Prices!$B$4/$B$6,0) -> 0.6 | D23: =IF($B$7>0,Prices!G26*Prices!$B$4/$B$7,0) -> 1.1111111 | E23: =IF($B$8>0,Prices!I26*Prices!$B$4/$B$8,0) -> 0.48387097 | F23: =IF($B$9>0,Prices!K26*Prices!$B$4/$B$9,0) -> 0
A24: 2010 | B24: =IF($B$5>0,Prices!C27*Prices!$B$4/$B$5,0) -> 0.6 | C24: =IF($B$6>0,Prices!E27*Prices!$B$4/$B$6,0) -> 0.6 | D24: =IF($B$7>0,Prices!G27*Prices!$B$4/$B$7,0) -> 0 | E24: =IF($B$8>0,Prices!I27*Prices!$B$4/$B$8,0) -> 0.96774194 | F24: =IF($B$9>0,Prices!K27*Prices!$B$4/$B$9,0) -> 0.9375
A25: 2011 | B25: =IF($B$5>0,Prices!C28*Prices!$B$4/$B$5,0) -> 0.6 | C25: =IF($B$6>0,Prices!E28*Prices!$B$4/$B$6,0) -> 0.6 | D25: =IF($B$7>0,Prices!G28*Prices!$B$4/$B$7,0) -> 0.55555556 | E25: =IF($B$8>0,Prices!I28*Prices!$B$4/$B$8,0) -> 0 | F25: =IF($B$9>0,Prices!K28*Prices!$B$4/$B$9,0) -> 0
... A38: 2024 | B38: =IF($B$5>0,Prices!C41*Prices!$B$4/$B$5,0) -> 0.6 | C38: =IF($B$6>0,Prices!E41*Prices!$B$4/$B$6,0) -> 0.6 | D38: =IF($B$7>0,Prices!G41*Prices!$B$4/$B$7,0) -> 0.55555556 | E38: =IF($B$8>0,Prices!I41*Prices!$B$4/$B$8,0) -> 0 | F38: =IF($B$9>0,Prices!K41*Prices!$B$4/$B$9,0) -> 0

Sheet Business case
A1: Business case: premiums are not Jio’s revenue
A2: A licensed insurer holds the premiums and carries the risk. Jio earns distribution and data fees.
A3: Inputs
A4: Payout per trigger day (₹) | B4: =Prices!B4 -> 300
A5: Payout share (claims ÷ premiums) | B5: =Prices!B5 -> 0.6
A6: Jio’s fee share, low | B6: 0.15
A7: Jio’s fee share, high | B7: 0.25
A9: Kavach Plus · one delivery app
A10: Riders covered | B10: 50000
A11: Price per rider per month (₹) | B11: =Prices!K9 -> 208.33333
A12: Premiums a year (₹ crore) | B12: =B10*B11*12/10^7 -> 12.5
A13: Back to riders as claims (₹ crore) | B13: =B12*B5 -> 7.5
A14: Jio’s fees, low (₹ crore) | B14: =B12*B6 -> 1.875
A15: Jio’s fees, high (₹ crore) | B15: =B12*B7 -> 3.125
A16: One city-wide flood day: every rider paid once (₹ crore) | B16: =B10*B4/10^7 -> 1.5
A17: Most one rider can get in a year (₹) | B17: =Prices!E9*B4 -> 1500
A19: Kavach Basic · at recharge
A20: Jio users (crore) | B20: 50 | C20: Approximate, as used in our pitch.
A21: Share who buy | B21: 0.01 | C21: Illustrative adoption, not a forecast.
A22: Price per person per month (₹) | B22: =Prices!B6 -> 29 | C22: The Basic price floor (₹29). City prices run up to ₹52.
A23: Policies | B23: =B20*10^7*B21 -> 5000000
A24: Premiums a year (₹ crore) | B24: =B23*B22*12/10^7 -> 174
A25: Back to people as claims (₹ crore) | B25: =B24*B5 -> 104.4
A26: Jio’s fees, low (₹ crore) | B26: =B24*B6 -> 26.1
A27: Jio’s fees, high (₹ crore) | B27: =B24*B7 -> 43.5
A29: Ahmedabad example: 1 lakh customers
A30: Customers | B30: 100000
A31: Premiums a year (₹ crore) | B31: =B30*Prices!K13*12/10^7 -> 3.48
A32: Expected claims a year (₹ crore) | B32: =B30*Prices!H13*B4/10^7 -> 1.92
